Traceback (most recent call last):
  File "/usr/local/lib/python3.10/dist-packages/jupyter_cache/executors/utils.py", line 58, in single_nb_execution
    executenb(
  File "/usr/local/lib/python3.10/dist-packages/nbclient/client.py", line 1305, in execute
    return NotebookClient(nb=nb, resources=resources, km=km, **kwargs).execute()
  File "/usr/local/lib/python3.10/dist-packages/jupyter_core/utils/__init__.py", line 166, in wrapped
    return loop.run_until_complete(inner)
  File "/usr/lib/python3.10/asyncio/base_events.py", line 649, in run_until_complete
    return future.result()
  File "/usr/local/lib/python3.10/dist-packages/nbclient/client.py", line 705, in async_execute
    await self.async_execute_cell(
  File "/usr/local/lib/python3.10/dist-packages/nbclient/client.py", line 1058, in async_execute_cell
    await self._check_raise_for_error(cell, cell_index, exec_reply)
  File "/usr/local/lib/python3.10/dist-packages/nbclient/client.py", line 914, in _check_raise_for_error
    raise CellExecutionError.from_cell_and_msg(cell, exec_reply_content)
nbclient.exceptions.CellExecutionError: An error occurred while executing the following cell:
------------------
data_base = connect(
  host='localhost',
  user='root',
  password=''
)

cur = data_base.cursor()

query = 'show databases'

cur.execute(query)

data_bases = cur.fetchall()

for data in data_bases:
  print(data)


# mycursor.execute("SELECT * FROM petallength")

# myresult = mycursor.fetchall()

# for x in myresult:
#   print(x)

------------------


[0;31m[0m
[0;31mOSError[0mTraceback (most recent call last)
[0;32m/usr/local/lib/python3.10/dist-packages/pymysql/connections.py[0m in [0;36mconnect[0;34m(self, sock)[0m
[1;32m    615[0m                         [0;32mtry[0m[0;34m:[0m[0;34m[0m[0;34m[0m[0m
[0;32m--> 616[0;31m                             sock = socket.create_connection(
[0m[1;32m    617[0m                                 [0;34m([0m[0mself[0m[0;34m.[0m[0mhost[0m[0;34m,[0m [0mself[0m[0;34m.[0m[0mport[0m[0;34m)[0m[0;34m,[0m [0mself[0m[0;34m.[0m[0mconnect_timeout[0m[0;34m,[0m [0;34m**[0m[0mkwargs[0m[0;34m[0m[0;34m[0m[0m

[0;32m/usr/lib/python3.10/socket.py[0m in [0;36mcreate_connection[0;34m(address, timeout, source_address)[0m
[1;32m    844[0m         [0;32mtry[0m[0;34m:[0m[0;34m[0m[0;34m[0m[0m
[0;32m--> 845[0;31m             [0;32mraise[0m [0merr[0m[0;34m[0m[0;34m[0m[0m
[0m[1;32m    846[0m         [0;32mfinally[0m[0;34m:[0m[0;34m[0m[0;34m[0m[0m

[0;32m/usr/lib/python3.10/socket.py[0m in [0;36mcreate_connection[0;34m(address, timeout, source_address)[0m
[1;32m    832[0m                 [0msock[0m[0;34m.[0m[0mbind[0m[0;34m([0m[0msource_address[0m[0;34m)[0m[0;34m[0m[0;34m[0m[0m
[0;32m--> 833[0;31m             [0msock[0m[0;34m.[0m[0mconnect[0m[0;34m([0m[0msa[0m[0;34m)[0m[0;34m[0m[0;34m[0m[0m
[0m[1;32m    834[0m             [0;31m# Break explicitly a reference cycle[0m[0;34m[0m[0;34m[0m[0m

[0;31mOSError[0m: [Errno 99] Cannot assign requested address

During handling of the above exception, another exception occurred:

[0;31mOperationalError[0mTraceback (most recent call last)
[0;32m<ipython-input-3-2d4ec58ccd00>[0m in [0;36m<cell line: 1>[0;34m()[0m
[0;32m----> 1[0;31m data_base = connect(
[0m[1;32m      2[0m   [0mhost[0m[0;34m=[0m[0;34m'localhost'[0m[0;34m,[0m[0;34m[0m[0;34m[0m[0m
[1;32m      3[0m   [0muser[0m[0;34m=[0m[0;34m'root'[0m[0;34m,[0m[0;34m[0m[0;34m[0m[0m
[1;32m      4[0m   [0mpassword[0m[0;34m=[0m[0;34m''[0m[0;34m[0m[0;34m[0m[0m
[1;32m      5[0m )

[0;32m/usr/local/lib/python3.10/dist-packages/pymysql/connections.py[0m in [0;36m__init__[0;34m(self, user, password, host, database, unix_socket, port, charset, sql_mode, read_default_file, conv, use_unicode, client_flag, cursorclass, init_command, connect_timeout, read_default_group, autocommit, local_infile, max_allowed_packet, defer_connect, auth_plugin_map, read_timeout, write_timeout, bind_address, binary_prefix, program_name, server_public_key, ssl, ssl_ca, ssl_cert, ssl_disabled, ssl_key, ssl_verify_cert, ssl_verify_identity, compress, named_pipe, passwd, db)[0m
[1;32m    350[0m             [0mself[0m[0;34m.[0m[0m_sock[0m [0;34m=[0m [0;32mNone[0m[0;34m[0m[0;34m[0m[0m
[1;32m    351[0m         [0;32melse[0m[0;34m:[0m[0;34m[0m[0;34m[0m[0m
[0;32m--> 352[0;31m             [0mself[0m[0;34m.[0m[0mconnect[0m[0;34m([0m[0;34m)[0m[0;34m[0m[0;34m[0m[0m
[0m[1;32m    353[0m [0;34m[0m[0m
[1;32m    354[0m     [0;32mdef[0m [0m__enter__[0m[0;34m([0m[0mself[0m[0;34m)[0m[0;34m:[0m[0;34m[0m[0;34m[0m[0m

[0;32m/usr/local/lib/python3.10/dist-packages/pymysql/connections.py[0m in [0;36mconnect[0;34m(self, sock)[0m
[1;32m    666[0m                 [0;32mif[0m [0mDEBUG[0m[0;34m:[0m[0;34m[0m[0;34m[0m[0m
[1;32m    667[0m                     [0mprint[0m[0;34m([0m[0mexc[0m[0;34m.[0m[0mtraceback[0m[0;34m)[0m[0;34m[0m[0;34m[0m[0m
[0;32m--> 668[0;31m                 [0;32mraise[0m [0mexc[0m[0;34m[0m[0;34m[0m[0m
[0m[1;32m    669[0m [0;34m[0m[0m
[1;32m    670[0m             [0;31m# If e is neither DatabaseError or IOError, It's a bug.[0m[0;34m[0m[0;34m[0m[0m

[0;31mOperationalError[0m: (2003, "Can't connect to MySQL server on 'localhost' ([Errno 99] Cannot assign requested address)")

